94 - Fetching orders from Shopify API
2025-01-08 03:49:51.320 | INFO     | sync_service:sync_recent_sales:70 - Found order 1: #1001
2025-01-08 03:49:51.321 | INFO     | sync_service:sync_recent_sales:71 - Processing order: #1001
2025-01-08 03:49:51.934 | INFO     | sync_service:sync_recent_sales:74 - Order #1001 already exists, skipping
2025-01-08 03:49:51.935 | INFO     | sync_service:sync_recent_sales:70 - Found order 2: #1002
2025-01-08 03:49:51.935 | INFO     | sync_service:sync_recent_sales:71 - Processing order: #1002
2025-01-08 03:49:53.371 | INFO     | sync_service:sync_recent_sales:91 - Created sale record: #1002 with ID 5
2025-01-08 03:49:53.371 | INFO     | sync_service:sync_recent_sales:96 - Processing item: Konohanano 'Hops, Unfiltered' Doburoku for order #1002
2025-01-08 03:49:53.371 | INFO     | sync_service:sync_recent_sales:96 - Processing item: Konohanano Momoshu for order #1002
2025-01-08 03:49:53.782 | ERROR    | sync_service:sync_recent_sales:116 - Error syncing sales: (raised as a result of Query-invoked autoflush; consider using a session.no_autoflush block if this flush is occurring prematurely)
(psycopg2.errors.ForeignKeyViolation) insert or update on table "sale_items" violates foreign key constraint "sale_items_sale_id_fkey"
DETAIL:  Key (sale_id)=(5) is not present in table "sales".

[SQL: INSERT INTO sale_items (sale_id, title, quantity, original_price, discounted_price, sku) SELECT p0::INTEGER, p1::VARCHAR, p2::INTEGER, p3::NUMERIC(10, 2), p4::NUMERIC(10, 2), p5::VARCHAR FROM (VALUES (%(sale_id__0)s, %(title__0)s, %(quantity__0)s, %( ... 190 characters truncated ... 1, p2, p3, p4, p5, sen_counter) ORDER BY sen_counter RETURNING sale_items.id, sale_items.id AS id__1]
[parameters: {'discounted_price__0': Decimal('66.43'), 'original_price__0': Decimal('91.00'), 'sku__0': 'SCNKO007', 'quantity__0': 1, 'sale_id__0': 5, 'title__0': "Konohanano 'Hops, Unfiltered' Doburoku", 'discounted_price__1': Decimal('64.24'), 'original_price__1': Decimal('88.00'), 'sku__1': 'SCNKO012', 'quantity__1': 1, 'sale_id__1': 5, 'title__1': 'Konohanano Momoshu'}]
(Background on this error at: https://sqlalche.me/e/20/gkpj)
Job "sync_job (trigger: interval[1 day, 0:00:00], next run at: 2025-01-09 03:48:03 UTC)" raised an exception
Traceback (most recent call last):
  File "/home/runner/boxhero-sync/.pythonlibs/lib/python3.12/site-packages/sqlalchemy/engine/base.py", line 2112, in _exec_insertmany_context
    dialect.do_execute(
  File "/home/runner/boxhero-sync/.pythonlibs/lib/python3.12/site-packages/sqlalchemy/engine/default.py", line 922, in do_execute
    cursor.execute(statement, parameters)
psycopg2.errors.ForeignKeyViolation: insert or update on table "sale_items" violates foreign key constraint "sale_items_sale_id_fkey"
DETAIL:  Key (sale_id)=(5) is not present in table "sales".


The above exception was the direct cause of the following exception:

Traceback (most recent call last):
  File "/home/runner/boxhero-sync/main.py", line 25, in sync_job
    service.sync_recent_sales(days=1)
  File "/home/runner/boxhero-sync/sync_service.py", line 108, in sync_recent_sales
    sync_log.records_processed = (sync_log.records_processed or 0) + 1
                                  ^^^^^^^^^^^^^^^^^^^^^^^^^^
  File "/home/runner/boxhero-sync/.pythonlibs/lib/python3.12/site-packages/sqlalchemy/orm/attributes.py", line 566, in __get__
    return self.impl.get(state, dict_)  # type: ignore[no-any-return]
           ^^^^^^^^^^^^^^^^^^^^^^^^^^^
  File "/home/runner/boxhero-sync/.pythonlibs/lib/python3.12/site-packages/sqlalchemy/orm/attributes.py", line 1086, in get
    value = self._fire_loader_callables(state, key, passive)
            ^^^^^^^^^^^^^^^^^^^^^^^^^^^^^^^^^^^^^^^^^^^^^^^^
  File "/home/runner/boxhero-sync/.pythonlibs/lib/python3.12/site-packages/sqlalchemy/orm/attributes.py", line 1116, in _fire_loader_callables
    return state._load_expired(state, passive)
           ^^^^^^^^^^^^^^^^^^^^^^^^^^^^^^^^^^^
  File "/home/runner/boxhero-sync/.pythonlibs/lib/python3.12/site-packages/sqlalchemy/orm/state.py", line 798, in _load_expired
    self.manager.expired_attribute_loader(self, toload, passive)
  File "/home/runner/boxhero-sync/.pythonlibs/lib/python3.12/site-packages/sqlalchemy/orm/loading.py", line 1649, in load_scalar_attributes
    result = load_on_ident(
             ^^^^^^^^^^^^^^
  File "/home/runner/boxhero-sync/.pythonlibs/lib/python3.12/site-packages/sqlalchemy/orm/loading.py", line 505, in load_on_ident
    return load_on_pk_identity(
           ^^^^^^^^^^^^^^^^^^^^
  File "/home/runner/boxhero-sync/.pythonlibs/lib/python3.12/site-packages/sqlalchemy/orm/loading.py", line 690, in load_on_pk_identity
    session.execute(
  File "/home/runner/boxhero-sync/.pythonlibs/lib/python3.12/site-packages/sqlalchemy/orm/session.py", line 2308, in execute
    return self._execute_internal(
           ^^^^^^^^^^^^^^^^^^^^^^^
  File "/home/runner/boxhero-sync/.pythonlibs/lib/python3.12/site-packages/sqlalchemy/orm/session.py", line 2169, in _execute_internal
    ) = compile_state_cls.orm_pre_session_exec(
        ^^^^^^^^^^^^^^^^^^^^^^^^^^^^^^^^^^^^^^^
  File "/home/runner/boxhero-sync/.pythonlibs/lib/python3.12/site-packages/sqlalchemy/orm/context.py", line 551, in orm_pre_session_exec
    session._autoflush()
  File "/home/runner/boxhero-sync/.pythonlibs/lib/python3.12/site-packages/sqlalchemy/orm/session.py", line 3021, in _autoflush
    raise e.with_traceback(sys.exc_info()[2])
  File "/home/runner/boxhero-sync/.pythonlibs/lib/python3.12/site-packages/sqlalchemy/orm/session.py", line 3010, in _autoflush
    self.flush()
  File "/home/runner/boxhero-sync/.pythonlibs/lib/python3.12/site-packages/sqlalchemy/orm/session.py", line 4312, in flush
    self._flush(objects)
  File "/home/runner/boxhero-sync/.pythonlibs/lib/python3.12/site-packages/sqlalchemy/orm/session.py", line 4447, in _flush
    with util.safe_reraise():
         ^^^^^^^^^^^^^^^^^^^
  File "/home/runner/boxhero-sync/.pythonlibs/lib/python3.12/site-packages/sqlalchemy/util/langhelpers.py", line 146, in __exit__
    raise exc_value.with_traceback(exc_tb)
  File "/home/runner/boxhero-sync/.pythonlibs/lib/python3.12/site-packages/sqlalchemy/orm/session.py", line 4408, in _flush
    flush_context.execute()
  File "/home/runner/boxhero-sync/.pythonlibs/lib/python3.12/site-packages/sqlalchemy/orm/unitofwork.py", line 466, in execute
    rec.execute(self)
  File "/home/runner/boxhero-sync/.pythonlibs/lib/python3.12/site-packages/sqlalchemy/orm/unitofwork.py", line 642, in execute
    util.preloaded.orm_persistence.save_obj(
  File "/home/runner/boxhero-sync/.pythonlibs/lib/python3.12/site-packages/sqlalchemy/orm/persistence.py", line 93, in save_obj
    _emit_insert_statements(
  File "/home/runner/boxhero-sync/.pythonlibs/lib/python3.12/site-packages/sqlalchemy/orm/persistence.py", line 1136, in _emit_insert_statements
    result = connection.execute(
             ^^^^^^^^^^^^^^^^^^^
  File "/home/runner/boxhero-sync/.pythonlibs/lib/python3.12/site-packages/sqlalchemy/engine/base.py", line 1416, in execute
    return meth(
           ^^^^^
  File "/home/runner/boxhero-sync/.pythonlibs/lib/python3.12/site-packages/sqlalchemy/sql/elements.py", line 516, in _execute_on_connection
    return connection._execute_clauseelement(
           ^^^^^^^^^^^^^^^^^^^^^^^^^^^^^^^^^^
  File "/home/runner/boxhero-sync/.pythonlibs/lib/python3.12/site-packages/sqlalchemy/engine/base.py", line 1639, in _execute_clauseelement
    ret = self._execute_context(
          ^^^^^^^^^^^^^^^^^^^^^^
  File "/home/runner/boxhero-sync/.pythonlibs/lib/python3.12/site-packages/sqlalchemy/engine/base.py", line 1843, in _execute_context
    return self._exec_insertmany_context(
           ^^^^^^^^^^^^^^^^^^^^^^^^^^^^^^
  File "/home/runner/boxhero-sync/.pythonlibs/lib/python3.12/site-packages/sqlalchemy/engine/base.py", line 2120, in _exec_insertmany_context
    self._handle_dbapi_exception(
  File "/home/runner/boxhero-sync/.pythonlibs/lib/python3.12/site-packages/sqlalchemy/engine/base.py", line 2343, in _handle_dbapi_exception
    raise sqlalchemy_exception.with_traceback(exc_info[2]) from e
  File "/home/runner/boxhero-sync/.pythonlibs/lib/python3.12/site-packages/sqlalchemy/engine/base.py", line 2112, in _exec_insertmany_context
    dialect.do_execute(
  File "/home/runner/boxhero-sync/.pythonlibs/lib/python3.12/site-packages/sqlalchemy/engine/default.py", line 922, in do_execute
    cursor.execute(statement, parameters)
sqlalchemy.exc.IntegrityError: (raised as a result of Query-invoked autoflush; consider using a session.no_autoflush block if this flush is occurring prematurely)
(psycopg2.errors.ForeignKeyViolation) insert or update on table "sale_items" violates foreign key constraint "sale_items_sale_id_fkey"
DETAIL:  Key (sale_id)=(5) is not present in table "sales".

[SQL: INSERT INTO sale_items (sale_id, title, quantity, original_price, discounted_price, sku) SELECT p0::INTEGER, p1::VARCHAR, p2::INTEGER, p3::NUMERIC(10, 2), p4::NUMERIC(10, 2), p5::VARCHAR FROM (VALUES (%(sale_id__0)s, %(title__0)s, %(quantity__0)s, %( ... 190 characters truncated ... 1, p2, p3, p4, p5, sen_counter) ORDER BY sen_counter RETURNING sale_items.id, sale_items.id AS id__1]
[parameters: {'discounted_price__0': Decimal('66.43'), 'original_price__0': Decimal('91.00'), 'sku__0': 'SCNKO007', 'quantity__0': 1, 'sale_id__0': 5, 'title__0': "Konohanano 'Hops, Unfiltered' Doburoku", 'discounted_price__1': Decimal('64.24'), 'original_price__1': Decimal('88.00'), 'sku__1': 'SCNKO012', 'quantity__1': 1, 'sale_id__1': 5, 'title__1': 'Konohanano Momoshu'}]
(Background on this error at: https://sqlalche.me/e/20/gkpj)

During handling of the above exception, another exception occurred:

Traceback (most recent call last):
  File "/home/runner/boxhero-sync/.pythonlibs/lib/python3.12/site-packages/apscheduler/executors/base.py", line 125, in run_job
    retval = job.func(*job.args, **job.kwargs)
             ^^^^^^^^^^^^^^^^^^^^^^^^^^^^^^^^^
  File "/home/runner/boxhero-sync/main.py", line 28, in sync_job
    logger.error(f"Sync job failed: {str(e)}", exc_info=True)
  File "/home/runner/boxhero-sync/.pythonlibs/lib/python3.12/site-packages/loguru/_logger.py", line 2056, in error
    __self._log("ERROR", False, __self._options, __message, args, kwargs)
  File "/home/runner/boxhero-sync/.pythonlibs/lib/python3.12/site-packages/loguru/_logger.py", line 2021, in _log
    log_record["message"] = message.format(*args, **kwargs)
                            ^^^^^^^^^^^^^^^^^^^^^^^^^^^^^^^
KeyError: "'discounted_price__0'"